#VRML_SIM R2023b utf8

EXTERNPROTO "https://raw.githubusercontent.com/cyberbotics/webots/R2023b/projects/objects/backgrounds/protos/TexturedBackground.proto"
EXTERNPROTO "https://raw.githubusercontent.com/cyberbotics/webots/R2023b/projects/objects/backgrounds/protos/TexturedBackgroundLight.proto"
EXTERNPROTO "https://raw.githubusercontent.com/cyberbotics/webots/R2023b/projects/objects/floors/protos/Floor.proto"

WorldInfo {
  info [
    ""
  ]
}
Viewpoint {
  orientation 0.010196307699851127 -0.9961643438943403 -0.08690589889557802 5.553342592166407
  position -11.751983527868179 -1.462057070988495 10.48600158374778
}
TexturedBackground {
}
TexturedBackgroundLight {
}
Floor {
  size 8 8
  appearance Appearance {
    texture ImageTexture {
      url [
        "../../../FieldMap.JPG"
      ]
    }
    textureTransform TextureTransform {
      scale 0.063 0.063
    }
  }
}
Robot {
  translation -0.0414689 0.0592181 5.85309e-13
  rotation 2.31518e-08 9.58981e-09 1 -0.785395307179586
  children [
    Camera {
      translation -0.3 4.89845e-18 0.11
      rotation 0 0 1 -3.141592653589793
      width 1920
      height 1080
      lens Lens {
      }
    }
    RangeFinder {
      translation -0.3 4.89845e-18 0.11
      rotation 0 0 1 -3.141592653589793
      width 1920
      height 1080
      maxRange 15
      lens Lens {
      }
    }
    Shape {
      appearance DEF base_link_material PBRAppearance {
        baseColor 0.792157 0.819608 0.933333
        roughness 1
        metalness 0
      }
      geometry DEF base_link Mesh {
        url [
          "D:/Documents/Code/Brian/agent/meshes/base_link.STL"
        ]
      }
    }
    HingeJoint {
      jointParameters HingeJointParameters {
        axis 0 1 -4e-06
        anchor -0.2 -0.19 0.1
      }
      device [
        RotationalMotor {
          name "joint_fll"
          maxTorque 10000
        }
        PositionSensor {
          name "joint_fll_sensor"
        }
      ]
      endPoint Solid {
        translation -0.2 -0.19 0.1
        rotation -1 0 0 1.5708
        children [
          Shape {
            appearance DEF link_fll_material PBRAppearance {
              baseColor 0.792157 0.819608 0.933333
              roughness 1
              metalness 0
            }
            geometry DEF link_fll Mesh {
              url [
                "D:/Documents/Code/Brian/agent/meshes/link_fll.STL"
              ]
            }
          }
          HingeJoint {
            jointParameters HingeJointParameters {
              axis 0 0 -1
              anchor 0.19365 0.05 -0.02
            }
            device [
              RotationalMotor {
                name "joint_flf"
                maxTorque 10000
              }
              PositionSensor {
                name "joint_flf_sensor"
              }
            ]
            endPoint Solid {
              translation 0.19365 0.05 -0.02
              rotation 0 0 -1 0
              children [
                Shape {
                  appearance DEF link_flf_material PBRAppearance {
                    baseColor 0.792157 0.819608 0.933333
                    roughness 1
                    metalness 0
                  }
                  geometry DEF link_flf Mesh {
                    url [
                      "D:/Documents/Code/Brian/agent/meshes/link_flf.STL"
                    ]
                  }
                }
              ]
              name "link_flf"
              boundingObject USE link_flf
              physics Physics {
                density -1
                mass 0.589008
                centerOfMass [
                  -0.109366 0.009146 0.011333
                ]
                inertiaMatrix [
                  0.0003700288 0.006139244 0.006440685
                  0.0004858436 -8.589585e-05 7.182972e-06
                ]
              }
            }
          }
        ]
        name "link_fll"
        boundingObject USE link_fll
        physics Physics {
          density -1
          mass 1.035619
          centerOfMass [
            0.096825 0.025 0.02
          ]
          inertiaMatrix [
            0.001344422 0.006322759 0.007391017
            -0.001377215 -7.604585e-05 -1.963495e-05
          ]
        }
      }
    }
    HingeJoint {
      jointParameters HingeJointParameters {
        axis 0 1 -4e-06
        anchor -0.2 0.19 0.1
      }
      device [
        RotationalMotor {
          name "joint_frl"
          maxTorque 10000
        }
        PositionSensor {
          name "joint_frl_sensor"
        }
      ]
      endPoint Solid {
        translation -0.2 0.19 0.1
        rotation -1 0 0 1.5708
        children [
          Shape {
            appearance DEF link_frl_material PBRAppearance {
              baseColor 0.792157 0.819608 0.933333
              roughness 1
              metalness 0
            }
            geometry DEF link_frl Mesh {
              url [
                "D:/Documents/Code/Brian/agent/meshes/link_frl.STL"
              ]
            }
          }
          HingeJoint {
            jointParameters HingeJointParameters {
              axis 0 0 -1
              anchor 0.19365 0.05 0.02
            }
            device [
              RotationalMotor {
                name "joint_frf"
                maxTorque 10000
              }
              PositionSensor {
                name "joint_frf_sensor"
              }
            ]
            endPoint Solid {
              translation 0.19365 0.05 0.02
              rotation 0 0 -1 0
              children [
                Shape {
                  appearance DEF link_frf_material PBRAppearance {
                    baseColor 0.792157 0.819608 0.933333
                    roughness 1
                    metalness 0
                  }
                  geometry DEF link_frf Mesh {
                    url [
                      "D:/Documents/Code/Brian/agent/meshes/link_frf.STL"
                    ]
                  }
                }
              ]
              name "link_frf"
              boundingObject USE link_frf
              physics Physics {
                density -1
                mass 0.589008
                centerOfMass [
                  -0.109366 0.009146 -0.011333
                ]
                inertiaMatrix [
                  0.0003700288 0.006139244 0.006440685
                  0.0004858436 8.589585e-05 -7.182972e-06
                ]
              }
            }
          }
        ]
        name "link_frl"
        boundingObject USE link_frl
        physics Physics {
          density -1
          mass 1.035619
          centerOfMass [
            0.096825 0.025 -0.02
          ]
          inertiaMatrix [
            0.001344422 0.006322759 0.007391017
            -0.001377215 7.604585e-05 1.963495e-05
          ]
        }
      }
    }
    HingeJoint {
      jointParameters HingeJointParameters {
        axis 0 1 -4e-06
        anchor 0.2 -0.19 0.1
      }
      device [
        RotationalMotor {
          name "joint_bll"
          maxTorque 10000
        }
        PositionSensor {
          name "joint_bll_sensor"
        }
      ]
      endPoint Solid {
        translation 0.2 -0.19 0.1
        rotation -1 0 0 1.5708
        children [
          Shape {
            appearance DEF link_bll_material PBRAppearance {
              baseColor 0.792157 0.819608 0.933333
              roughness 1
              metalness 0
            }
            geometry DEF link_bll Mesh {
              url [
                "D:/Documents/Code/Brian/agent/meshes/link_bll.STL"
              ]
            }
          }
          HingeJoint {
            jointParameters HingeJointParameters {
              axis 0 0 -1
              anchor 0.19365 0.05 -0.02
            }
            device [
              RotationalMotor {
                name "joint_blf"
                maxTorque 10000
              }
              PositionSensor {
                name "joint_blf_sensor"
              }
            ]
            endPoint Solid {
              translation 0.19365 0.05 -0.02
              rotation 0 0 -1 0
              children [
                Shape {
                  appearance DEF link_blf_material PBRAppearance {
                    baseColor 0.792157 0.819608 0.933333
                    roughness 1
                    metalness 0
                  }
                  geometry DEF link_blf Mesh {
                    url [
                      "D:/Documents/Code/Brian/agent/meshes/link_blf.STL"
                    ]
                  }
                }
              ]
              name "link_blf"
              boundingObject USE link_blf
              physics Physics {
                density -1
                mass 0.589008
                centerOfMass [
                  -0.109366 0.009146 0.011333
                ]
                inertiaMatrix [
                  0.0003700288 0.006139244 0.006440685
                  0.0004858436 -8.589585e-05 7.182972e-06
                ]
              }
            }
          }
        ]
        name "link_bll"
        boundingObject USE link_bll
        physics Physics {
          density -1
          mass 1.035619
          centerOfMass [
            0.096825 0.025 0.02
          ]
          inertiaMatrix [
            0.001344422 0.006322759 0.007391017
            -0.001377215 -7.604585e-05 -1.963495e-05
          ]
        }
      }
    }
    HingeJoint {
      jointParameters HingeJointParameters {
        axis 0 1 -4e-06
        anchor 0.2 0.19 0.1
      }
      device [
        RotationalMotor {
          name "joint_brl"
          maxTorque 10000
        }
        PositionSensor {
          name "joint_brl_sensor"
        }
      ]
      endPoint Solid {
        translation 0.2 0.19 0.1
        rotation -1 0 0 1.5708
        children [
          Shape {
            appearance DEF link_brl_material PBRAppearance {
              baseColor 0.792157 0.819608 0.933333
              roughness 1
              metalness 0
            }
            geometry DEF link_brl Mesh {
              url [
                "D:/Documents/Code/Brian/agent/meshes/link_brl.STL"
              ]
            }
          }
          HingeJoint {
            jointParameters HingeJointParameters {
              axis 0 0 -1
              anchor 0.19365 0.05 0.02
            }
            device [
              RotationalMotor {
                name "joint_brf"
                maxTorque 10000
              }
              PositionSensor {
                name "joint_brf_sensor"
              }
            ]
            endPoint Solid {
              translation 0.19365 0.05 0.02
              rotation 0 0 -1 0
              children [
                Shape {
                  appearance DEF link_brf_material PBRAppearance {
                    baseColor 0.792157 0.819608 0.933333
                    roughness 1
                    metalness 0
                  }
                  geometry DEF link_brf Mesh {
                    url [
                      "D:/Documents/Code/Brian/agent/meshes/link_brf.STL"
                    ]
                  }
                }
              ]
              name "link_brf"
              boundingObject USE link_brf
              physics Physics {
                density -1
                mass 0.589008
                centerOfMass [
                  -0.109366 0.009146 -0.011333
                ]
                inertiaMatrix [
                  0.0003700288 0.006139244 0.006440685
                  0.0004858436 8.589585e-05 -7.182972e-06
                ]
              }
            }
          }
        ]
        name "link_brl"
        boundingObject USE link_brl
        physics Physics {
          density -1
          mass 1.035619
          centerOfMass [
            0.096825 0.025 -0.02
          ]
          inertiaMatrix [
            0.001344422 0.006322759 0.007391017
            -0.001377215 7.604585e-05 1.963495e-05
          ]
        }
      }
    }
  ]
  name "Agent"
  boundingObject USE base_link
  physics Physics {
    density -1
    mass 36.15708
    centerOfMass [
      0 0 0.1
    ]
    inertiaMatrix [
      0.394051 1.206332 1.360334
      4.235165e-18 -6.383062e-17 -3.417758e-18
    ]
  }
  controller "agent_controller"
}
