#VRML_SIM R2023b utf8

EXTERNPROTO "https://raw.githubusercontent.com/cyberbotics/webots/R2023b/projects/objects/backgrounds/protos/TexturedBackground.proto"
EXTERNPROTO "https://raw.githubusercontent.com/cyberbotics/webots/R2023b/projects/objects/backgrounds/protos/TexturedBackgroundLight.proto"
EXTERNPROTO "https://raw.githubusercontent.com/cyberbotics/webots/R2023b/projects/objects/floors/protos/Floor.proto"

WorldInfo {
  info [
    ""
  ]
  basicTimeStep 8
}
Viewpoint {
  orientation 0.28894119512098226 -0.2898860481405929 -0.9124029070840844 4.616488815019945
  position 0.2625147610855412 -10.970452636674363 7.421183108606903
}
TexturedBackground {
}
TexturedBackgroundLight {
}
Floor {
  size 8 8
  appearance Appearance {
    texture ImageTexture {
      url [
        "../../../FieldMap.JPG"
      ]
    }
    textureTransform TextureTransform {
      scale 0.063 0.063
    }
  }
}
Robot {
  rotation 0 0 1 0.785
  children [
    Accelerometer {
    }
    Gyro {
    }
    Camera {
      translation -0.3 4.89845e-18 0.19
      rotation -0.2588180265806088 1.7318101778568887e-07 0.965926099200601 -3.1415853071795863
      fieldOfView 1.57
      width 1920
      height 1080
      lens Lens {
      }
    }
    RangeFinder {
      translation -0.3 4.89845e-18 0.11
      rotation 0 0 1 -3.141592653589793
      width 1920
      height 1080
      maxRange 15
      lens Lens {
      }
    }
    Shape {
      appearance DEF base_link_material PBRAppearance {
        baseColor 0.792157 0.819608 0.933333
        roughness 1
        metalness 0
      }
      geometry DEF base_link Mesh {
        url [
          "D:/Documents/Code/Brian/agent/meshes/base_link.STL"
        ]
      }
    }
    HingeJoint {
      jointParameters HingeJointParameters {
        axis 0 1 -4e-06
        anchor -0.2 -0.19 0.1
      }
      device [
        RotationalMotor {
          name "joint_fll"
          controlPID 100 0 0
          maxTorque 100
        }
        PositionSensor {
          name "joint_fll_sensor"
        }
      ]
      endPoint Solid {
        translation -0.18403081672891206 -0.19324178284975263 0.08459711899304594
        rotation -0.999994260133699 -0.0021736936094675064 0.002598991294359356 1.549955680105165
        children [
          Shape {
            appearance DEF link_fll_material PBRAppearance {
              baseColor 0.792157 0.819608 0.933333
              roughness 1
              metalness 0
            }
            geometry DEF link_fll Mesh {
              url [
                "D:/Documents/Code/Brian/agent/meshes/link_fll.STL"
              ]
            }
          }
          HingeJoint {
            jointParameters HingeJointParameters {
              axis 0 0 -1
              anchor 0.19365 0.05 -0.02
            }
            device [
              RotationalMotor {
                name "joint_flf"
                controlPID 100 0 0
                maxTorque 10000
              }
              PositionSensor {
                name "joint_flf_sensor"
              }
            ]
            endPoint Solid {
              translation 0.19365 0.05 -0.02
              rotation 0 0 -1 0
              children [
                Shape {
                  appearance DEF link_flf_material PBRAppearance {
                    baseColor 0.792157 0.819608 0.933333
                    roughness 1
                    metalness 0
                  }
                  geometry DEF link_flf Mesh {
                    url [
                      "D:/Documents/Code/Brian/agent/meshes/link_flf.STL"
                    ]
                  }
                }
              ]
              name "link_flf"
              boundingObject USE link_flf
              physics Physics {
                density -1
                mass 0.589008
                centerOfMass [
                  -0.109366 0.009146 0.011333
                ]
                inertiaMatrix [
                  0.0003700288 0.006139244 0.006440685
                  0.0004858436 -8.589585e-05 7.182972e-06
                ]
              }
            }
          }
        ]
        name "link_fll"
        boundingObject USE link_fll
        physics Physics {
          density -1
          mass 1.035619
          centerOfMass [
            0.096825 0.025 0.02
          ]
          inertiaMatrix [
            0.001344422 0.006322759 0.007391017
            -0.001377215 -7.604585e-05 -1.963495e-05
          ]
        }
      }
    }
    HingeJoint {
      jointParameters HingeJointParameters {
        axis 0 1 -4e-06
        anchor -0.2 0.19 0.1
      }
      device [
        RotationalMotor {
          name "joint_frl"
          controlPID 100 0 0
          maxTorque 10000
        }
        PositionSensor {
          name "joint_frl_sensor"
        }
      ]
      endPoint Solid {
        translation -0.19042433973321674 0.20030308296281563 0.09890870575381375
        rotation -0.9999653913225637 -0.005918478879297291 0.005847030431552065 1.5907532125955186
        children [
          Shape {
            appearance DEF link_frl_material PBRAppearance {
              baseColor 0.792157 0.819608 0.933333
              roughness 1
              metalness 0
            }
            geometry DEF link_frl Mesh {
              url [
                "D:/Documents/Code/Brian/agent/meshes/link_frl.STL"
              ]
            }
          }
          HingeJoint {
            jointParameters HingeJointParameters {
              axis 0 0 -1
              anchor 0.19365 0.05 0.02
            }
            device [
              RotationalMotor {
                name "joint_frf"
                controlPID 100 0 0
                maxTorque 10000
              }
              PositionSensor {
                name "joint_frf_sensor"
              }
            ]
            endPoint Solid {
              translation 0.19365 0.05 0.02
              rotation 0 0 -1 0
              children [
                Shape {
                  appearance DEF link_frf_material PBRAppearance {
                    baseColor 0.792157 0.819608 0.933333
                    roughness 1
                    metalness 0
                  }
                  geometry DEF link_frf Mesh {
                    url [
                      "D:/Documents/Code/Brian/agent/meshes/link_frf.STL"
                    ]
                  }
                }
              ]
              name "link_frf"
              boundingObject USE link_frf
              physics Physics {
                density -1
                mass 0.589008
                centerOfMass [
                  -0.109366 0.009146 -0.011333
                ]
                inertiaMatrix [
                  0.0003700288 0.006139244 0.006440685
                  0.0004858436 8.589585e-05 -7.182972e-06
                ]
              }
            }
          }
        ]
        name "link_frl"
        boundingObject USE link_frl
        physics Physics {
          density -1
          mass 1.035619
          centerOfMass [
            0.096825 0.025 -0.02
          ]
          inertiaMatrix [
            0.001344422 0.006322759 0.007391017
            -0.001377215 7.604585e-05 1.963495e-05
          ]
        }
      }
    }
    HingeJoint {
      jointParameters HingeJointParameters {
        axis 0 1 -4e-06
        anchor 0.2 -0.19 0.1
      }
      device [
        RotationalMotor {
          name "joint_bll"
          controlPID 100 0 0
          maxTorque 10000
        }
        PositionSensor {
          name "joint_bll_sensor"
        }
      ]
      endPoint Solid {
        translation 0.2194636078894736 -0.2014691601859856 0.08615663566627507
        rotation -0.999864928887361 0.01174875851226683 -0.011493069846348609 1.5710069647742226
        children [
          Shape {
            appearance DEF link_bll_material PBRAppearance {
              baseColor 0.792157 0.819608 0.933333
              roughness 1
              metalness 0
            }
            geometry DEF link_bll Mesh {
              url [
                "D:/Documents/Code/Brian/agent/meshes/link_bll.STL"
              ]
            }
          }
          HingeJoint {
            jointParameters HingeJointParameters {
              axis 0 0 -1
              anchor 0.19365 0.05 -0.02
            }
            device [
              RotationalMotor {
                name "joint_blf"
                controlPID 100 0 0
                maxTorque 10000
              }
              PositionSensor {
                name "joint_blf_sensor"
              }
            ]
            endPoint Solid {
              translation 0.19365 0.05 -0.02
              rotation 0 0 -1 0
              children [
                Shape {
                  appearance DEF link_blf_material PBRAppearance {
                    baseColor 0.792157 0.819608 0.933333
                    roughness 1
                    metalness 0
                  }
                  geometry DEF link_blf Mesh {
                    url [
                      "D:/Documents/Code/Brian/agent/meshes/link_blf.STL"
                    ]
                  }
                }
              ]
              name "link_blf"
              boundingObject USE link_blf
              physics Physics {
                density -1
                mass 0.589008
                centerOfMass [
                  -0.109366 0.009146 0.011333
                ]
                inertiaMatrix [
                  0.0003700288 0.006139244 0.006440685
                  0.0004858436 -8.589585e-05 7.182972e-06
                ]
              }
            }
          }
        ]
        name "link_bll"
        boundingObject USE link_bll
        physics Physics {
          density -1
          mass 1.035619
          centerOfMass [
            0.096825 0.025 0.02
          ]
          inertiaMatrix [
            0.001344422 0.006322759 0.007391017
            -0.001377215 -7.604585e-05 -1.963495e-05
          ]
        }
      }
    }
    HingeJoint {
      jointParameters HingeJointParameters {
        axis 0 1 -4e-06
        anchor 0.2 0.19 0.1
      }
      device [
        RotationalMotor {
          name "joint_brl"
          controlPID 100 0 0
          maxTorque 10000
        }
        PositionSensor {
          name "joint_brl_sensor"
        }
      ]
      endPoint Solid {
        translation 0.22840454570671628 0.1934313474147353 0.09715350207855857
        rotation -0.9999891699918039 0.0033697350024615835 -0.003210106714211684 1.5642347142448363
        children [
          Shape {
            appearance DEF link_brl_material PBRAppearance {
              baseColor 0.792157 0.819608 0.933333
              roughness 1
              metalness 0
            }
            geometry DEF link_brl Mesh {
              url [
                "D:/Documents/Code/Brian/agent/meshes/link_brl.STL"
              ]
            }
          }
          HingeJoint {
            jointParameters HingeJointParameters {
              axis 0 0 -1
              anchor 0.19365 0.05 0.02
            }
            device [
              RotationalMotor {
                name "joint_brf"
                controlPID 100 0 0
                maxTorque 10000
              }
              PositionSensor {
                name "joint_brf_sensor"
              }
            ]
            endPoint Solid {
              translation 0.19365 0.05 0.02
              rotation 0 0 -1 0
              children [
                Shape {
                  appearance DEF link_brf_material PBRAppearance {
                    baseColor 0.792157 0.819608 0.933333
                    roughness 1
                    metalness 0
                  }
                  geometry DEF link_brf Mesh {
                    url [
                      "D:/Documents/Code/Brian/agent/meshes/link_brf.STL"
                    ]
                  }
                }
              ]
              name "link_brf"
              boundingObject USE link_brf
              physics Physics {
                density -1
                mass 0.589008
                centerOfMass [
                  -0.109366 0.009146 -0.011333
                ]
                inertiaMatrix [
                  0.0003700288 0.006139244 0.006440685
                  0.0004858436 8.589585e-05 -7.182972e-06
                ]
              }
            }
          }
        ]
        name "link_brl"
        boundingObject USE link_brl
        physics Physics {
          density -1
          mass 1.035619
          centerOfMass [
            0.096825 0.025 -0.02
          ]
          inertiaMatrix [
            0.001344422 0.006322759 0.007391017
            -0.001377215 7.604585e-05 1.963495e-05
          ]
        }
      }
    }
  ]
  name "Agent"
  boundingObject USE base_link
  physics Physics {
    density -1
    mass 100
    centerOfMass [
      0 0 0.1
    ]
    inertiaMatrix [
      0.394051 1.206332 1.360334
      4.235165e-18 -6.383062e-17 -3.417758e-18
    ]
  }
  controller "agent_controller"
  supervisor TRUE
}
